Workbook
Name NativeTimeline_Order_Date: #N/A
Name Slicer_Category: #N/A
Name Slicer_Category1: #N/A
Name Slicer_Region: #N/A
Name Slicer_Region1: #N/A
Name Slicer_Segment: #N/A
Name Slicer_Segment1: #N/A
Name Slicer_Ship_Mode: #N/A
Name Slicer_Ship_Mode1: #N/A
Name Slicer_State: #N/A
Name Slicer_Year: #N/A
Name Timeline_Order_Date: #N/A

Sheet Data
A1: Row ID | B1: Order ID | C1: Year | D1: Order Date | E1: Ship Date | F1: Ship Mode | G1: Customer ID | H1: Customer Name | I1: Segment | J1: Country | K1: City | L1: State | M1: Postal Code | N1: Region | O1: Product ID | P1: Category | Q1: Sub-Category | R1: Product Name | S1: Sales | T1: Quantity | U1: Discount | V1: Profit
A2: 1 | B2: CA-2013-152156 | C2: =YEAR(Data!$D2) -> 2013 | D2: 41587 | E2: 41590 | F2: Second Class | G2: CG-12520 | H2: Claire Gute | I2: Consumer | J2: United States | K2: Henderson | L2: Kentucky | M2: 42420 | N2: South | O2: FUR-BO-10001798 | P2: Furniture | Q2: Bookcases | R2: Bush Somerset Collection Bookcase | S2: 261.96 | T2: 2 | U2: 0 | V2: 41.9136
A3: 2 | B3: CA-2013-152156 | C3: =YEAR(Data!$D3) -> 2013 | D3: 41587 | E3: 41590 | F3: Second Class | G3: CG-12520 | H3: Claire Gute | I3: Consumer | J3: United States | K3: Henderson | L3: Kentucky | M3: 42420 | N3: South | O3: FUR-CH-10000454 | P3: Furniture | Q3: Chairs | R3: Hon Deluxe Fabric Upholstered Stacking Chairs, Rounded Back | S3: 731.94 | T3: 3 | U3: 0 | V3: 219.582
A4: 3 | B4: CA-2013-138688 | C4: =YEAR(Data!$D4) -> 2013 | D4: 41438 | E4: 41442 | F4: Second Class | G4: DV-13045 | H4: Darrin Van Huff | I4: Corporate | J4: United States | K4: Los Angeles | L4: California | M4: 90036 | N4: West | O4: OFF-LA-10000240 | P4: Office Supplies | Q4: Labels | R4: Self-Adhesive Address Labels for Typewriters by Universal | S4: 14.62 | T4: 2 | U4: 0 | V4: 6.8714
A5: 4 | B5: US-2012-108966 | C5: =YEAR(Data!$D5) -> 2012 | D5: 41193 | E5: 41200 | F5: Standard Class | G5: SO-20335 | H5: Sean O'Donnell | I5: Consumer | J5: United States | K5: Fort Lauderdale | L5: Florida | M5: 33311 | N5: South | O5: FUR-TA-10000577 | P5: Furniture | Q5: Tables | R5: Bretford CR4500 Series Slim Rectangular Table | S5: 957.5775 | T5: 5 | U5: 0.45 | V5: -383.031
A6: 5 | B6: US-2012-108966 | C6: =YEAR(Data!$D6) -> 2012 | D6: 41193 | E6: 41200 | F6: Standard Class | G6: SO-20335 | H6: Sean O'Donnell | I6: Consumer | J6: United States | K6: Fort Lauderdale | L6: Florida | M6: 33311 | N6: South | O6: OFF-ST-10000760 | P6: Office Supplies | Q6: Storage | R6: Eldon Fold 'N Roll Cart System | S6: 22.368 | T6: 2 | U6: 0.2 | V6: 2.5164
A7: 6 | B7: CA-2011-115812 | C7: =YEAR(Data!$D7) -> 2011 | D7: 40703 | E7: 40708 | F7: Standard Class | G7: BH-11710 | H7: Brosina Hoffman | I7: Consumer | J7: United States | K7: Los Angeles | L7: California | M7: 90032 | N7: West | O7: FUR-FU-10001487 | P7: Furniture | Q7: Furnishings | R7: Eldon Expressions Wood and Plastic Desk Accessories, Cherry Wood | S7: 48.86 | T7: 7 | U7: 0 | V7: 14.1694
A8: 7 | B8: CA-2011-115812 | C8: =YEAR(Data!$D8) -> 2011 | D8: 40703 | E8: 40708 | F8: Standard Class | G8: BH-11710 | H8: Brosina Hoffman | I8: Consumer | J8: United States | K8: Los Angeles | L8: California | M8: 90032 | N8: West | O8: OFF-AR-10002833 | P8: Office Supplies | Q8: Art | R8: Newell 322 | S8: 7.28 | T8: 4 | U8: 0 | V8: 1.9656
A9: 8 | B9: CA-2011-115812 | C9: =YEAR(Data!$D9) -> 2011 | D9: 40703 | E9: 40708 | F9: Standard Class | G9: BH-11710 | H9: Brosina Hoffman | I9: Consumer | J9: United States | K9: Los Angeles | L9: California | M9: 90032 | N9: West | O9: TEC-PH-10002275 | P9: Technology | Q9: Phones | R9: Mitel 5320 IP Phone VoIP phone | S9: 907.152 | T9: 6 | U9: 0.2 | V9: 90.7152
A10: 9 | B10: CA-2011-115812 | C10: =YEAR(Data!$D10) -> 2011 | D10: 40703 | E10: 40708 | F10: Standard Class | G10: BH-11710 | H10: Brosina Hoffman | I10: Consumer | J10: United States | K10: Los Angeles | L10: California | M10: 90032 | N10: West | O10: OFF-BI-10003910 | P10: Office Supplies | Q10: Binders | R10: DXL Angle-View Binders with Locking Rings by Samsill | S10: 18.504 | T10: 3 | U10: 0.2 | V10: 5.7825
A11: 10 | B11: CA-2011-115812 | C11: =YEAR(Data!$D11) -> 2011 | D11: 40703 | E11: 40708 | F11: Standard Class | G11: BH-11710 | H11: Brosina Hoffman | I11: Consumer | J11: United States | K11: Los Angeles | L11: California | M11: 90032 | N11: West | O11: OFF-AP-10002892 | P11: Office Supplies | Q11: Appliances | R11: Belkin F5C206VTEL 6 Outlet Surge | S11: 114.9 | T11: 5 | U11: 0 | V11: 34.47
A12: 11 | B12: CA-2011-115812 | C12: =YEAR(Data!$D12) -> 2011 | D12: 40703 | E12: 40708 | F12: Standard Class | G12: BH-11710 | H12: Brosina Hoffman | I12: Consumer | J12: United States | K12: Los Angeles | L12: California | M12: 90032 | N12: West | O12: FUR-TA-10001539 | P12: Furniture | Q12: Tables | R12: Chromcraft Rectangular Conference Tables | S12: 1706.184 | T12: 9 | U12: 0.2 | V12: 85.3092
A13: 12 | B13: CA-2011-115812 | C13: =YEAR(Data!$D13) -> 2011 | D13: 40703 | E13: 40708 | F13: Standard Class | G13: BH-11710 | H13: Brosina Hoffman | I13: Consumer | J13: United States | K13: Los Angeles | L13: California | M13: 90032 | N13: West | O13: TEC-PH-10002033 | P13: Technology | Q13: Phones | R13: Konftel 250 Conference phone - Charcoal black | S13: 911.424 | T13: 4 | U13: 0.2 | V13: 68.3568
... A2235: 2234 | B2235: CA-2012-123232 | C2235: =YEAR(Data!$D2235) -> 2012 | D2235: 41257 | E2235: 41259 | F2235: Second Class | G2235: DJ-13630 | H2235: Doug Jacobs | I2235: Consumer | J2235: United States | K2235: Portland | L2235: Oregon | M2235: 97206 | N2235: West | O2235: TEC-PH-10001051 | P2235: Technology | Q2235: Phones | R2235: HTC One | S2235: 319.968 | T2235: 4 | U2235: 0.2 | V2235: 35.9964
A2236: 2235 | B2236: CA-2014-104066 | C2236: =YEAR(Data!$D2236) -> 2014 | D2236: 41979 | E2236: 41984 | F2236: Standard Class | G2236: QJ-19255 | H2236: Quincy Jones | I2236: Corporate | J2236: United States | K2236: Burlington | L2236: Vermont | M2236: 05408 | N2236: East | O2236: TEC-AC-10001013 | P2236: Technology | Q2236: Accessories | R2236: Logitech ClearChat Comfort/USB Headset H390 | S2236: 205.03 | T2236: 7 | U2236: 0 | V2236: 67.6599
A2237: 2236 | B2237: CA-2012-145849 | C2237: =YEAR(Data!$D2237) -> 2012 | D2237: 41167 | E2237: 41169 | F2237: Second Class | G2237: CT-11995 | H2237: Carol Triggs | I2237: Consumer | J2237: United States | K2237: Indianapolis | L2237: Indiana | M2237: 46203 | N2237: Central | O2237: OFF-ST-10000025 | P2237: Office Supplies | Q2237: Storage | R2237: Fellowes Stor/Drawer Steel Plus Storage Drawers | S2237: 190.86 | T2237: 2 | U2237: 0 | V2237: 11.4516
A2238: 2237 | B2238: CA-2012-145849 | C2238: =YEAR(Data!$D2238) -> 2012 | D2238: 41167 | E2238: 41169 | F2238: Second Class | G2238: CT-11995 | H2238: Carol Triggs | I2238: Consumer | J2238: United States | K2238: Indianapolis | L2238: Indiana | M2238: 46203 | N2238: Central | O2238: OFF-AR-10000817 | P2238: Office Supplies | Q2238: Art | R2238: Manco Dry-Lighter Erasable Highlighter | S2238: 24.32 | T2238: 8 | U2238: 0 | V2238: 8.2688
A2239: 2238 | B2239: CA-2013-122322 | C2239: =YEAR(Data!$D2239) -> 2013 | D2239: 41471 | E2239: 41477 | F2239: Standard Class | G2239: RH-19510 | H2239: Rick Huthwaite | I2239: Home Office | J2239: United States | K2239: Provo | L2239: Utah | M2239: 84604 | N2239: West | O2239: OFF-SU-10000952 | P2239: Office Supplies | Q2239: Supplies | R2239: Fiskars Home & Office Scissors | S2239: 44.4 | T2239: 5 | U2239: 0 | V2239: 12.432
A2240: 2239 | B2240: CA-2014-166849 | C2240: =YEAR(Data!$D2240) -> 2014 | D2240: 41750 | E2240: 41756 | F2240: Standard Class | G2240: SJ-20125 | H2240: Sanjit Jacobs | I2240: Home Office | J2240: United States | K2240: Chicago | L2240: Illinois | M2240: 60610 | N2240: Central | O2240: FUR-FU-10004597 | P2240: Furniture | Q2240: Furnishings | R2240: Eldon Cleatmat Chair Mats for Medium Pile Carpets | S2240: 44.4 | T2240: 2 | U2240: 0.6 | V2240: -52.17
A2241: 2240 | B2241: CA-2013-146633 | C2241: =YEAR(Data!$D2241) -> 2013 | D2241: 41594 | E2241: 41596 | F2241: Second Class | G2241: TG-21310 | H2241: Toby Gnade | I2241: Consumer | J2241: United States | K2241: Los Angeles | L2241: California | M2241: 90049 | N2241: West | O2241: OFF-BI-10003527 | P2241: Office Supplies | Q2241: Binders | R2241: Fellowes PB500 Electric Punch Plastic Comb Binding Machine with Manual Bind | S2241: 1016.792 | T2241: 1 | U2241: 0.2 | V2241: 381.297
A2242: 2241 | B2242: CA-2013-146633 | C2242: =YEAR(Data!$D2242) -> 2013 | D2242: 41594 | E2242: 41596 | F2242: Second Class | G2242: TG-21310 | H2242: Toby Gnade | I2242: Consumer | J2242: United States | K2242: Los Angeles | L2242: California | M2242: 90049 | N2242: West | O2242: OFF-BI-10002982 | P2242: Office Supplies | Q2242: Binders | R2242: Avery Self-Adhesive Photo Pockets for Polaroid Photos | S2242: 38.136 | T2242: 7 | U2242: 0.2 | V2242: 13.3476
A2243: 2242 | B2243: US-2013-126893 | C2243: =YEAR(Data!$D2243) -> 2013 | D2243: 41605 | E2243: 41610 | F2243: Standard Class | G2243: CT-11995 | H2243: Carol Triggs | I2243: Consumer | J2243: United States | K2243: Philadelphia | L2243: Pennsylvania | M2243: 19134 | N2243: East | O2243: TEC-PH-10004165 | P2243: Technology | Q2243: Phones | R2243: Mitel MiVoice 5330e IP Phone | S2243: 494.982 | T2243: 3 | U2243: 0.4 | V2243: -115.4958
A2244: 2243 | B2244: CA-2014-103380 | C2244: =YEAR(Data!$D2244) -> 2014 | D2244: 41965 | E2244: 41969 | F2244: Standard Class | G2244: BF-11005 | H2244: Barry Franz | I2244: Home Office | J2244: United States | K2244: Pasadena | L2244: California | M2244: 91104 | N2244: West | O2244: OFF-ST-10003442 | P2244: Office Supplies | Q2244: Storage | R2244: Eldon Portable Mobile Manager | S2244: 56.56 | T2244: 2 | U2244: 0 | V2244: 15.2712
A2245: 2244 | B2245: CA-2014-103380 | C2245: =YEAR(Data!$D2245) -> 2014 | D2245: 41965 | E2245: 41969 | F2245: Standard Class | G2245: BF-11005 | H2245: Barry Franz | I2245: Home Office | J2245: United States | K2245: Pasadena | L2245: California | M2245: 91104 | N2245: West | O2245: OFF-AR-10003856 | P2245: Office Supplies | Q2245: Art | R2245: Newell 344 | S2245: 5.56 | T2245: 2 | U2245: 0 | V2245: 1.4456
A2246: 2245 | B2246: CA-2014-103380 | C2246: =YEAR(Data!$D2246) -> 2014 | D2246: 41965 | E2246: 41969 | F2246: Standard Class | G2246: BF-11005 | H2246: Barry Franz | I2246: Home Office | J2246: United States | K2246: Pasadena | L2246: California | M2246: 91104 | N2246: West | O2246: OFF-FA-10004248 | P2246: Office Supplies | Q2246: Fasteners | R2246: Advantus T-Pin Paper Clips | S2246: 9.02 | T2246: 2 | U2246: 0 | V2246: 3.5178
A2247: 2246 | B2247: CA-2014-103380 | C2247: =YEAR(Data!$D2247) -> 2014 | D2247: 41965 | E2247: 41969 | F2247: Standard Class | G2247: BF-11005 | H2247: Barry Franz | I2247: Home Office | J2247: United States | K2247: Pasadena | L2247: California | M2247: 91104 | N2247: West | O2247: OFF-AP-10001492 | P2247: Office Supplies | Q2247: Appliances | R2247: Acco Six-Outlet Power Strip, 4' Cord Length | S2247: 8.62 | T2247: 1 | U2247: 0 | V2247: 2.2412
A2248: 2247 | B2248: CA-2014-103380 | C2248: =YEAR(Data!$D2248) -> 2014 | D2248: 41965 | E2248: 41969 | F2248: Standard Class | G2248: BF-11005 | H2248: Barry Franz | I2248: Home Office | J2248: United States | K2248: Pasadena | L2248: California | M2248: 91104 | N2248: West | O2248: TEC-PH-10004165 | P2248: Technology | Q2248: Phones | R2248: Mitel MiVoice 5330e IP Phone | S2248: 659.976 | T2248: 3 | U2248: 0.2 | V2248: 49.4982
... A5275: 5274 | B5275: US-2013-158309 | C5275: =YEAR(Data!$D5275) -> 2013 | D5275: 41605 | E5275: 41608 | F5275: First Class | G5275: PA-19060 | H5275: Pete Armstrong | I5275: Home Office | J5275: United States | K5275: Miami | L5275: Florida | M5275: 33142 | N5275: South | O5275: OFF-BI-10000145 | P5275: Office Supplies | Q5275: Binders | R5275: Zipper Ring Binder Pockets | S5275: 3.744 | T5275: 4 | U5275: 0.7 | V5275: -2.6208
A5276: 5275 | B5276: CA-2012-162887 | C5276: =YEAR(Data!$D5276) -> 2012 | D5276: 41220 | E5276: 41222 | F5276: Second Class | G5276: SV-20785 | H5276: Stewart Visinsky | I5276: Consumer | J5276: United States | K5276: Burlington | L5276: Vermont | M5276: 05408 | N5276: East | O5276: FUR-CH-10000595 | P5276: Furniture | Q5276: Chairs | R5276: Safco Contoured Stacking Chairs | S5276: 715.2 | T5276: 3 | U5276: 0 | V5276: 178.8
A5277: 5276 | B5277: CA-2014-147333 | C5277: =YEAR(Data!$D5277) -> 2014 | D5277: 41988 | E5277: 41994 | F5277: Standard Class | G5277: KL-16555 | H5277: Kelly Lampkin | I5277: Corporate | J5277: United States | K5277: Fayetteville | L5277: Arkansas | M5277: 72701 | N5277: South | O5277: TEC-AC-10004469 | P5277: Technology | Q5277: Accessories | R5277: Microsoft Sculpt Comfort Mouse | S5277: 159.8 | T5277: 4 | U5277: 0 | V5277: 70.312
A5278: 5277 | B5278: CA-2014-147333 | C5278: =YEAR(Data!$D5278) -> 2014 | D5278: 41988 | E5278: 41994 | F5278: Standard Class | G5278: KL-16555 | H5278: Kelly Lampkin | I5278: Corporate | J5278: United States | K5278: Fayetteville | L5278: Arkansas | M5278: 72701 | N5278: South | O5278: TEC-AC-10003038 | P5278: Technology | Q5278: Accessories | R5278: Kingston Digital DataTraveler 16GB USB 2.0 | S5278: 44.75 | T5278: 5 | U5278: 0 | V5278: 8.5025
A5279: 5278 | B5279: CA-2011-113859 | C5279: =YEAR(Data!$D5279) -> 2011 | D5279: 40799 | E5279: 40803 | F5279: Standard Class | G5279: BC-11125 | H5279: Becky Castell | I5279: Home Office | J5279: United States | K5279: Odessa | L5279: Texas | M5279: 79762 | N5279: Central | O5279: FUR-CH-10004698 | P5279: Furniture | Q5279: Chairs | R5279: Padded Folding Chairs, Black, 4/Carton | S5279: 340.116 | T5279: 6 | U5279: 0.3 | V5279: -9.7176
A5280: 5279 | B5280: CA-2011-159681 | C5280: =YEAR(Data!$D5280) -> 2011 | D5280: 40884 | E5280: 40890 | F5280: Standard Class | G5280: PO-18850 | H5280: Patrick O'Brill | I5280: Consumer | J5280: United States | K5280: Virginia Beach | L5280: Virginia | M5280: 23464 | N5280: South | O5280: OFF-PA-10003641 | P5280: Office Supplies | Q5280: Paper | R5280: Xerox 1909 | S5280: 105.52 | T5280: 4 | U5280: 0 | V5280: 48.5392
A5281: 5280 | B5281: US-2014-104094 | C5281: =YEAR(Data!$D5281) -> 2014 | D5281: 41890 | E5281: 41894 | F5281: Standard Class | G5281: AG-10675 | H5281: Anna Gayman | I5281: Consumer | J5281: United States | K5281: Milwaukee | L5281: Wisconsin | M5281: 53209 | N5281: Central | O5281: TEC-AC-10002134 | P5281: Technology | Q5281: Accessories | R5281: Rosewill 107 Normal Keys USB Wired Standard Keyboard | S5281: 13.48 | T5281: 1 | U5281: 0 | V5281: 1.8872
A5282: 5281 | B5282: CA-2014-152709 | C5282: =YEAR(Data!$D5282) -> 2014 | D5282: 41920 | E5282: 41925 | F5282: Standard Class | G5282: DB-13210 | H5282: Dean Braden | I5282: Consumer | J5282: United States | K5282: Detroit | L5282: Michigan | M5282: 48234 | N5282: Central | O5282: OFF-ST-10001837 | P5282: Office Supplies | Q5282: Storage | R5282: SAFCO Mobile Desk Side File, Wire Frame | S5282: 85.52 | T5282: 2 | U5282: 0 | V5282: 22.2352
A5283: 5282 | B5283: CA-2012-105158 | C5283: =YEAR(Data!$D5283) -> 2012 | D5283: 41157 | E5283: 41162 | F5283: Standard Class | G5283: SP-20860 | H5283: Sung Pak | I5283: Corporate | J5283: United States | K5283: Rochester | L5283: Minnesota | M5283: 55901 | N5283: Central | O5283: FUR-FU-10001706 | P5283: Furniture | Q5283: Furnishings | R5283: Longer-Life Soft White Bulbs | S5283: 6.16 | T5283: 2 | U5283: 0 | V5283: 2.9568
A5284: 5283 | B5284: CA-2012-105158 | C5284: =YEAR(Data!$D5284) -> 2012 | D5284: 41157 | E5284: 41162 | F5284: Standard Class | G5284: SP-20860 | H5284: Sung Pak | I5284: Corporate | J5284: United States | K5284: Rochester | L5284: Minnesota | M5284: 55901 | N5284: Central | O5284: OFF-PA-10001970 | P5284: Office Supplies | Q5284: Paper | R5284: Xerox 1881 | S5284: 36.84 | T5284: 3 | U5284: 0 | V5284: 17.3148
A5285: 5284 | B5285: CA-2011-133424 | C5285: =YEAR(Data!$D5285) -> 2011 | D5285: 40632 | E5285: 40637 | F5285: Standard Class | G5285: Dl-13600 | H5285: Dorris liebe | I5285: Corporate | J5285: United States | K5285: Seattle | L5285: Washington | M5285: 98105 | N5285: West | O5285: OFF-ST-10002957 | P5285: Office Supplies | Q5285: Storage | R5285: Sterilite Show Offs Storage Containers | S5285: 15.84 | T5285: 3 | U5285: 0 | V5285: 0
A5286: 5285 | B5286: CA-2011-133424 | C5286: =YEAR(Data!$D5286) -> 2011 | D5286: 40632 | E5286: 40637 | F5286: Standard Class | G5286: Dl-13600 | H5286: Dorris liebe | I5286: Corporate | J5286: United States | K5286: Seattle | L5286: Washington | M5286: 98105 | N5286: West | O5286: OFF-LA-10002312 | P5286: Office Supplies | Q5286: Labels | R5286: Avery 490 | S5286: 44.4 | T5286: 3 | U5286: 0 | V5286: 22.2
A5287: 5286 | B5287: CA-2014-105991 | C5287: =YEAR(Data!$D5287) -> 2014 | D5287: 41765 | E5287: 41766 | F5287: First Class | G5287: LH-17020 | H5287: Lisa Hazard | I5287: Consumer | J5287: United States | K5287: Louisville | L5287: Colorado | M5287: 80027 | N5287: West | O5287: OFF-EN-10002600 | P5287: Office Supplies | Q5287: Envelopes | R5287: Redi-Strip #10 Envelopes, 4 1/8 x 9 1/2 | S5287: 21.24 | T5287: 9 | U5287: 0.2 | V5287: 7.434
...

Sheet Profit  wise region 
A3: Row Labels | B3: Sum of Sales | C3: Sum of Profit | F3: Region | G3: Sales | H3: Profit
A4: Central | B4: 501239.89 | C4: 39706.362 | F4: =A4 -> Central | G4: 501239.89 | H4: =GETPIVOTDATA("Sum of Profit",$A$3,"Region",A4) -> 39706.362
A5: East | B5: 678781.24 | C5: 91522.78 | F5: =A5 -> East | G5: 678781.24 | H5: =GETPIVOTDATA("Sum of Profit",$A$3,"Region",A5) -> 91522.78
A6: South | B6: 391721.91 | C6: 46749.43 | F6: =A6 -> South | G6: 391721.91 | H6: =GETPIVOTDATA("Sum of Profit",$A$3,"Region",A6) -> 46749.43
A7: West | B7: 725457.82 | C7: 108418.45 | F7: =A7 -> West | G7: 725457.82 | H7: =GETPIVOTDATA("Sum of Profit",$A$3,"Region",A7) -> 108418.45
A8: Grand Total | B8: 2297200.9 | C8: 286397.02

Sheet top 10 product by sales
B3: Row Labels | C3: Sum of Sales | F3: Product | G3: Sales
B4: Canon imageCLASS 2200 Advanced Copier | C4: 61599.824 | F4: =B4 -> Canon imageCLASS 2200 Advanced Copier | G4: =GETPIVOTDATA("Sales",$B$3,"Product Name",B4) -> 61599.824
B5: Fellowes PB500 Electric Punch Plastic Comb Binding Machine with Manual Bind | C5: 27453.384 | F5: =B5 -> Fellowes PB500 Electric Punch Plastic Comb Binding Machine with Manual Bind | G5: =GETPIVOTDATA("Sales",$B$3,"Product Name",B5) -> 27453.384
B6: Cisco TelePresence System EX90 Videoconferencing Unit | C6: 22638.48 | F6: =B6 -> Cisco TelePresence System EX90 Videoconferencing Unit | G6: =GETPIVOTDATA("Sales",$B$3,"Product Name",B6) -> 22638.48
B7: HON 5400 Series Task Chairs for Big and Tall | C7: 21870.576 | F7: =B7 -> HON 5400 Series Task Chairs for Big and Tall | G7: =GETPIVOTDATA("Sales",$B$3,"Product Name",B7) -> 21870.576
B8: GBC DocuBind TL300 Electric Binding System | C8: 19823.479 | F8: =B8 -> GBC DocuBind TL300 Electric Binding System | G8: =GETPIVOTDATA("Sales",$B$3,"Product Name",B8) -> 19823.479
B9: GBC Ibimaster 500 Manual ProClick Binding System | C9: 19024.5 | F9: =B9 -> GBC Ibimaster 500 Manual ProClick Binding System | G9: =GETPIVOTDATA("Sales",$B$3,"Product Name",B9) -> 19024.5
B10: Hewlett Packard LaserJet 3310 Copier | C10: 18839.686 | F10: =B10 -> Hewlett Packard LaserJet 3310 Copier | G10: =GETPIVOTDATA("Sales",$B$3,"Product Name",B10) -> 18839.686
B11: HP Designjet T520 Inkjet Large Format Printer - 24" Color | C11: 18374.895 | F11: =B11 -> HP Designjet T520 Inkjet Large Format Printer - 24" Color | G11: =GETPIVOTDATA("Sales",$B$3,"Product Name",B11) -> 18374.895
B12: GBC DocuBind P400 Electric Binding System | C12: 17965.068 | F12: =B12 -> GBC DocuBind P400 Electric Binding System | G12: =GETPIVOTDATA("Sales",$B$3,"Product Name",B12) -> 17965.068
B13: High Speed Automatic Electric Letter Opener | C13: 17030.312 | F13: =B13 -> High Speed Automatic Electric Letter Opener | G13: =GETPIVOTDATA("Sales",$B$3,"Product Name",B13) -> 17030.312
B14: Grand Total | C14: 244620.2

Sheet KPI
B2: Row Labels | C2: Sum of Sales | E2: Row Labels | F2: Sum of Profit
B3: 2011 | C3: 484247.5 | E3: 2011 | F3: 49543.974 | H3: Row Labels | I3: Sum of Quantity | L3: Row Labels | M3: Count of Order ID | O3: Row Labels | P3: Sum of Profit Margin
B4: 2012 | C4: 470532.51 | E4: 2012 | F4: 61618.604 | H4: 2011 | I4: 7581 | L4: 2011 | M4: 1993 | O4: 2011 | P4: 0.10231126
B5: 2013 | C5: 608473.83 | E5: 2013 | F5: 81726.931 | H5: 2012 | I5: 7979 | L5: 2012 | M5: 2102 | O5: 2012 | P5: 0.13095504
B6: 2014 | C6: 733947.02 | E6: 2014 | F6: 93507.513 | H6: 2013 | I6: 9810 | L6: 2013 | M6: 2580 | O6: 2013 | P6: 0.13431462
B7: Grand Total | C7: 2297200.9 | E7: Grand Total | F7: 286397.02 | H7: 2014 | I7: 12503 | L7: 2014 | M7: 3319 | O7: 2014 | P7: 0.12740363
F8: 286397.02 | H8: Grand Total | I8: 37873 | L8: Grand Total | M8: 9994 | O8: Grand Total | P8: 0.12467217
B9: TOTAL SALES | E9: TOTAL PROFIT | I9: 37873 | M9: 9994 | P9: 0.12467217
H10: TOTAL QUANTITY | L10: TOTAL ORDER
B14: Row Labels | C14: Count of Customer ID
B15: 2011 | C15: 1993
B16: 2012 | C16: 2102
B17: 2013 | C17: 2580
B18: 2014 | C18: 3319 | O18: Profit Margin
B19: Grand Total | C19: 9994
C20: 9994

Sheet category wise sales 
A3: Row Labels | B3: Sum of Sales
A4: Furniture | B4: 741999.8 | C4: =GETPIVOTDATA("Sales",$A$3,"Category","Furniture")/GETPIVOTDATA("Sales",$A$3) -> 0.32300171
A5: Office Supplies | B5: 719047.03 | C5: =GETPIVOTDATA("Sales",$A$3,"Category","Office Supplies")/GETPIVOTDATA("Sales",$A$3) -> 0.31301008
A6: Technology | B6: 836154.03 | C6: =GETPIVOTDATA("Sales",$A$3,"Category","Technology")/GETPIVOTDATA("Sales",$A$3) -> 0.36398821
A7: Grand Total | B7: 2297200.9

Sheet top 10 state by sales 
E2: State | F2: sum of sales
E3: =B7 -> Alabama | F3: =GETPIVOTDATA("Sales",$B$6,"State",B7) -> 19510.64
E4: =B8 -> Arizona | F4: =GETPIVOTDATA("Sales",$B$6,"State",B8) -> 35282.001
E5: =B9 -> Arkansas | F5: =GETPIVOTDATA("Sales",$B$6,"State",B9) -> 11678.13
B6: Row Labels | C6: Sum of Sales | E6: =B10 -> California | F6: =GETPIVOTDATA("Sales",$B$6,"State",B10) -> 457687.63
B7: Alabama | C7: 19510.64 | E7: =B11 -> Colorado | F7: =GETPIVOTDATA("Sales",$B$6,"State",B11) -> 32108.118
B8: Arizona | C8: 35282.001 | E8: =B12 -> Connecticut | F8: =GETPIVOTDATA("Sales",$B$6,"State",B12) -> 13384.357
B9: Arkansas | C9: 11678.13 | E9: =B13 -> Delaware | F9: =GETPIVOTDATA("Sales",$B$6,"State",B13) -> 27451.069
B10: California | C10: 457687.63 | E10: =B14 -> District of Columbia | F10: =GETPIVOTDATA("Sales",$B$6,"State",B14) -> 2865.02
B11: Colorado | C11: 32108.118 | E11: =B15 -> Florida | F11: =GETPIVOTDATA("Sales",$B$6,"State",B15) -> 89473.708
B12: Connecticut | C12: 13384.357 | E12: =B16 -> Georgia | F12: =GETPIVOTDATA("Sales",$B$6,"State",B16) -> 49095.84
B13: Delaware | C13: 27451.069 | E13: =B17 -> Idaho | F13: =GETPIVOTDATA("Sales",$B$6,"State",B17) -> 4382.486
B14: District of Columbia | C14: 2865.02 | E14: =B18 -> Illinois | F14: =GETPIVOTDATA("Sales",$B$6,"State",B18) -> 80166.101
B15: Florida | C15: 89473.708 | E15: =B19 -> Indiana | F15: =GETPIVOTDATA("Sales",$B$6,"State",B19) -> 53555.36
B16: Georgia | C16: 49095.84 | E16: =B20 -> Iowa | F16: =GETPIVOTDATA("Sales",$B$6,"State",B20) -> 4579.76
B17: Idaho | C17: 4382.486 | E17: =B21 -> Kansas | F17: =GETPIVOTDATA("Sales",$B$6,"State",B21) -> 2914.31
B18: Illinois | C18: 80166.101 | E18: =B22 -> Kentucky | F18: =GETPIVOTDATA("Sales",$B$6,"State",B22) -> 36591.75
... B51: Virginia | C51: 70636.72 | E51: =B55 -> Wyoming | F51: =GETPIVOTDATA("Sales",$B$6,"State",B55) -> 1603.136
B52: Washington | C52: 138641.27
B53: West Virginia | C53: 1209.824
B54: Wisconsin | C54: 32114.61
B55: Wyoming | C55: 1603.136
B56: Grand Total | C56: 2297200.9

Sheet top 10 customer
B2: Row Labels | C2: Sum of Sales
B3: Sean Miller | C3: 25043.05
B4: Tamara Chand | C4: 19052.218
B5: Raymond Buch | C5: 15117.339
B6: Tom Ashbrook | C6: 14595.62
B7: Adrian Barton | C7: 14473.571
B8: Ken Lonsdale | C8: 14175.229
B9: Sanjit Chand | C9: 14142.334
B10: Hunter Lopez | C10: 12873.298
B11: Sanjit Engle | C11: 12209.438
B12: Christopher Conant | C12: 12129.072
B13: Grand Total | C13: 153811.17

Sheet Sheet1
A3: 9 | B3: Sum of Sales
A4: First Class | B4: 2840.452
A5: Same Day | B5: 2180.344
A6: Second Class | B6: 10084.68
A7: Standard Class | B7: 18532.977
A8: Grand Total | B8: 33638.453

Sheet discount nd profit 
A2: Category | B2: Sub-Category | C2: Sum of Sales | F2: Category | G2: Sub-Category | H2: Sum of Sales
A3: Furniture | B3: Bookcases | C3: 114880 | F3: Furniture | G3: Bookcases | H3: 114880
A4: Furniture | B4: Chairs | C4: 328449.1 | F4: Furniture | G4: Chairs | H4: 328449.1
A5: Furniture | B5: Furnishings | C5: 91705.164 | F5: Furniture | G5: Furnishings | H5: 91705.164
A6: Furniture | B6: Tables | C6: 206965.53 | F6: Furniture | G6: Tables | H6: 206965.53
A7: Office Supplies | B7: Appliances | C7: 107532.16 | F7: Office Supplies | G7: Appliances | H7: 107532.16
A8: Office Supplies | B8: Art | C8: 27118.792 | F8: Office Supplies | G8: Art | H8: 27118.792
A9: Office Supplies | B9: Binders | C9: 203412.73 | F9: Office Supplies | G9: Binders | H9: 203412.73
A10: Office Supplies | B10: Envelopes | C10: 16476.402 | F10: Office Supplies | G10: Envelopes | H10: 16476.402
A11: Office Supplies | B11: Fasteners | C11: 3024.28 | F11: Office Supplies | G11: Fasteners | H11: 3024.28
A12: Office Supplies | B12: Labels | C12: 12486.312 | F12: Office Supplies | G12: Labels | H12: 12486.312
A13: Office Supplies | B13: Paper | C13: 78479.206 | F13: Office Supplies | G13: Paper | H13: 78479.206
A14: Office Supplies | B14: Storage | C14: 223843.61 | F14: Office Supplies | G14: Storage | H14: 223843.61
... A19: Technology | B19: Phones | C19: 330007.05 | F19: Technology | G19: Phones | H19: 330007.05

Sheet Sheet2
A1: Category | B1: Sub-Category | C1: Sum of Sales
A2: Furniture | B2: Bookcases | C2: 114880
A3: Furniture | B3: Chairs | C3: 328449.1
A4: Furniture | B4: Furnishings | C4: 91705.164
A5: Furniture | B5: Tables | C5: 206965.53
A6: Office Supplies | B6: Appliances | C6: 107532.16
A7: Office Supplies | B7: Art | C7: 27118.792
A8: Office Supplies | B8: Binders | C8: 203412.73
A9: Office Supplies | B9: Envelopes | C9: 16476.402
A10: Office Supplies | B10: Fasteners | C10: 3024.28
A11: Office Supplies | B11: Labels | C11: 12486.312
A12: Office Supplies | B12: Paper | C12: 78479.206
A13: Office Supplies | B13: Storage | C13: 223843.61
... A18: Technology | B18: Phones | C18: 330007.05

Sheet CY VS PY 
B4: Row Labels | C4: Sum of Sales | D4: Sum of Profit | E4: Sum of Quantity | F4: Count of Order ID | G4: Count of Customer ID | H4: Sum of Profit Margin
B5: 2011 | C5: 484247.5 | D5: 49543.974 | E5: 7581 | F5: 1993 | G5: 1993 | H5: 0.10231126
B6: 2012 | C6: 470532.51 | D6: 61618.604 | E6: 7979 | F6: 2102 | G6: 2102 | H6: 0.13095504
B7: 2013 | C7: 608473.83 | D7: 81726.931 | E7: 9810 | F7: 2580 | G7: 2580 | H7: 0.13431462
B8: 2014 | C8: 733947.02 | D8: 93507.513 | E8: 12503 | F8: 3319 | G8: 3319 | H8: 0.12740363
C11: =(GETPIVOTDATA("Sum of Sales",$B$4,"Years (Order Date)",2014)/GETPIVOTDATA("Sum of Sales",$B$4,"Years (Order Date)",2013))-1 -> 0.20620968 | D11: =(GETPIVOTDATA("Sum of Profit",$B$4,"Years (Order Date)",2014)/GETPIVOTDATA("Sum of Profit",$B$4,"Years (Order Date)",2013))-1 -> 0.14414566 | E11: =(GETPIVOTDATA("Sum of Quantity",$B$4,"Years (Order Date)",2014)/GETPIVOTDATA("Sum of Quantity",$B$4,"Years (Order Date)",2013))-1 -> 0.2745158 | F11: =(GETPIVOTDATA("Count of Order ID",$B$4,"Years (Order Date)",2014)/GETPIVOTDATA("Count of Order ID",$B$4,"Years (Order Date)",2013))-1 -> 0.28643411 | G11: =(GETPIVOTDATA("Count of Customer ID",$B$4,"Years (Order Date)",2014)/GETPIVOTDATA("Count of Customer ID",$B$4,"Years (Order Date)",2013))-1 -> 0.28643411 | H11: =(GETPIVOTDATA("Sum of Profit Margin",$B$4,"Years (Order Date)",2014)/GETPIVOTDATA("Sum of Profit Margin",$B$4,"Years (Order Date)",2013))-1 -> -0.051453757

Sheet combo chart 
A3: Row Labels | B3: Sum of Sales | C3: Sum of Profit
A4: 2011
A5: Feb | B5: 142.446 | C5: 57.1317
A6: Mar | B6: 1963.838 | C6: 367.7542
A7: Apr | B7: 529.282 | C7: 141.7633
A8: May | B8: 334.696 | C8: 119.455
A9: Jun | B9: 59.808 | C9: 19.4376
A10: Jul | B10: 599.454 | C10: 171.2402
A11: Aug | B11: 113.904 | C11: 43.326
A12: Sep | B12: 489.598 | C12: 141.3991
A13: Oct | B13: 19.99 | C13: 7.4872
A14: Nov | B14: 507.98 | C14: 236.0842
A15: Dec | B15: 935.446 | C15: 292.1779
A16: 2012
A17: Jan | B17: 187.18 | C17: 61.9478
A18: Apr | B18: 1185.19 | C18: 70.4597
A19: May | B19: 20.478 | C19: 6.9831
A20: Jun | B20: 37.404 | C20: 0.6646
A21: Jul | B21: 22.848 | C21: 7.4256
A22: Aug | B22: 225.076 | C22: 82.97
A23: Sep | B23: 443.624 | C23: 194.3397
A24: Oct | B24: 1911.04 | C24: 535.0912
A25: Nov | B25: 352.876 | C25: 121.4328
A26: Dec | B26: 516.768 | C26: 150.9728
A27: 2013
A28: Jan | B28: 91.28 | C28: 37.8112
A29: Feb | B29: 146.82 | C29: 73.41
A30: Mar | B30: 240.994 | C30: 49.0391
A31: Apr | B31: 483.965 | C31: 32.4138
A32: May | B32: 100.919 | C32: -7.8162
A33: Jun | B33: 147.144 | C33: 65.9567
A34: Jul | B34: 215.122 | C34: 13.601
A35: Aug | B35: 503.16 | C35: 141.9516
A36: Sep | B36: 980.778 | C36: 56.3784
A37: Oct | B37: 5150.37 | C37: 1855.9376
A38: Nov | B38: 325.114 | C38: 109.6564
A39: Dec | B39: 2549.232 | C39: 622.6206
A40: 2014
A41: Jan | B41: 1626.62 | C41: 145.6191
A42: Feb | B42: 433.508 | C42: 157.5508
...

Sheet final dashboard
B4: #VALUE!
